<?xml version="1.0" encoding="utf-8"?>
<!-- This URDF was automatically created by SolidWorks to URDF Exporter! Originally created by Stephen Brawner (brawner@gmail.com) 
     Commit Version: 1.6.0-4-g7f85cfe  Build Version: 1.6.7995.38578
     For more information, please see http://wiki.ros.org/sw_urdf_exporter -->
<robot
  name="ROBOT1010">
  <link
    name="base_link">
    <inertial>
      <origin
        xyz="-3.8858E-16 6.132E-05 0.48724"
        rpy="0 0 0" />
      <mass
        value="275.37" />
      <inertia
        ixx="29.428"
        ixy="-6.7312E-16"
        ixz="-2.6439E-15"
        iyy="30.097"
        iyz="-4.2543E-16"
        izz="15.99" />
    </inertial>
    <visual>
      <origin
        xyz="0 0 0"
        rpy="0 0 0" />
      <geometry>
        <mesh
          filename="package://my_robot_description/meshes/base_link.STL" />
      </geometry>
      <material
        name="">
        <color
          rgba="0.79216 0.81961 0.93333 1" />
      </material>
    </visual>
    <collision>
      <origin
        xyz="0 0 0"
        rpy="0 0 0" />
      <geometry>
        <mesh
          filename="package://my_robot_description/meshes/base_link.STL" />
      </geometry>
    </collision>
  </link>
  <link
    name="R_R00_Link">
    <inertial>
      <origin
        xyz="5.7685E-05 -0.00010433 0.065475"
        rpy="0 0 0" />
      <mass
        value="0.94896" />
      <inertia
        ixx="0.0029607"
        ixy="-1.0113E-06"
        ixz="5.2729E-06"
        iyy="0.0026222"
        iyz="-2.8851E-06"
        izz="0.0039906" />
    </inertial>
    <visual>
      <origin
        xyz="0 0 0"
        rpy="0 0 0" />
      <geometry>
        <mesh
          filename="package://my_robot_description/meshes/R_R00_Link.STL" />
      </geometry>
      <material
        name="">
        <color
          rgba="1 1 1 1" />
      </material>
    </visual>
    <collision>
      <origin
        xyz="0 0 0"
        rpy="0 0 0" />
      <geometry>
        <mesh
          filename="package://my_robot_description/meshes/R_R00_Link.STL" />
      </geometry>
    </collision>
  </link>
  <joint
    name="R_R00_Joint"
    type="fixed">
    <origin
      xyz="0.3015 0.001 0.8295"
      rpy="0 0 0" />
    <parent
      link="base_link" />
    <child
      link="R_R00_Link" />
    <axis
      xyz="0 0 0" />
  </joint>
  <link
    name="R_R01_Link">
    <inertial>
      <origin
        xyz="8.7738E-06 -0.010199 0.087734"
        rpy="0 0 0" />
      <mass
        value="3.6238" />
      <inertia
        ixx="0.011748"
        ixy="5.2402E-08"
        ixz="-5.1621E-07"
        iyy="0.010978"
        iyz="0.0014505"
        izz="0.011872" />
    </inertial>
    <visual>
      <origin
        xyz="0 0 0"
        rpy="0 0 0" />
      <geometry>
        <mesh
          filename="package://my_robot_description/meshes/R_R01_Link.STL" />
      </geometry>
      <material
        name="">
        <color
          rgba="1 1 1 1" />
      </material>
    </visual>
    <collision>
      <origin
        xyz="0 0 0"
        rpy="0 0 0" />
      <geometry>
        <mesh
          filename="package://my_robot_description/meshes/R_R01_Link.STL" />
      </geometry>
    </collision>
  </link>
  <joint
    name="R_R01_Joint"
    type="revolute">
    <origin
      xyz="0 0 0.101"
      rpy="0 0 0" />
    <parent
      link="R_R00_Link" />
    <child
      link="R_R01_Link" />
    <axis
      xyz="0 0 1" />
    <limit
      lower="-6.2832"
      upper="6.2832"
      effort="100.0"
      velocity="2.0" />
  </joint>
  <link
    name="R_R02_Link">
    <inertial>
      <origin
        xyz="-3.3956E-06 -0.090301 0.22698"
        rpy="0 0 0" />
      <mass
        value="10.025" />
      <inertia
        ixx="0.082438"
        ixy="-6.6884E-07"
        ixz="-6.9209E-08"
        iyy="0.082584"
        iyz="0.0010302"
        izz="0.023126" />
    </inertial>
    <visual>
      <origin
        xyz="0 0 0"
        rpy="0 0 0" />
      <geometry>
        <mesh
          filename="package://my_robot_description/meshes/R_R02_Link.STL" />
      </geometry>
      <material
        name="">
        <color
          rgba="1 1 1 1" />
      </material>
    </visual>
    <collision>
      <origin
        xyz="0 0 0"
        rpy="0 0 0" />
      <geometry>
        <mesh
          filename="package://my_robot_description/meshes/R_R02_Link.STL" />
      </geometry>
    </collision>
  </link>
  <joint
    name="R_R02_Joint"
    type="revolute">
    <origin
      xyz="0 -0.089 0.0915"
      rpy="0 0 0" />
    <parent
      link="R_R01_Link" />
    <child
      link="R_R02_Link" />
    <axis
      xyz="0 -1 0" />
    <limit
      lower="-6.2832"
      upper="6.2832"
      effort="100.0"
      velocity="2.0" />
  </joint>
  <link
    name="R_R03_Link">
    <inertial>
      <origin
        xyz="3.7353E-06 0.064682 0.19279"
        rpy="0 0 0" />
      <mass
        value="4.1459" />
      <inertia
        ixx="0.021426"
        ixy="-2.9841E-07"
        ixz="9.9667E-08"
        iyy="0.021"
        iyz="-0.00034616"
        izz="0.0057151" />
    </inertial>
    <visual>
      <origin
        xyz="0 0 0"
        rpy="0 0 0" />
      <geometry>
        <mesh
          filename="package://my_robot_description/meshes/R_R03_Link.STL" />
      </geometry>
      <material
        name="">
        <color
          rgba="1 1 1 1" />
      </material>
    </visual>
    <collision>
      <origin
        xyz="0 0 0"
        rpy="0 0 0" />
      <geometry>
        <mesh
          filename="package://my_robot_description/meshes/R_R03_Link.STL" />
      </geometry>
    </collision>
  </link>
  <joint
    name="R_R03_Joint"
    type="revolute">
    <origin
      xyz="0 -0.0209 0.552"
      rpy="0 0 0" />
    <parent
      link="R_R02_Link" />
    <child
      link="R_R03_Link" />
    <axis
      xyz="0 1 0" />
    <limit
      lower="-6.2832"
      upper="6.2832"
      effort="100.0"
      velocity="2.0" />
  </joint>
  <link
    name="R_R04_Link">
    <inertial>
      <origin
        xyz="-2.9867E-06 -0.059008 0.0041121"
        rpy="0 0 0" />
      <mass
        value="0.94334" />
      <inertia
        ixx="0.0014296"
        ixy="3.0514E-08"
        ixz="-4.9833E-08"
        iyy="0.0011354"
        iyz="0.00019671"
        izz="0.0012242" />
    </inertial>
    <visual>
      <origin
        xyz="0 0 0"
        rpy="0 0 0" />
      <geometry>
        <mesh
          filename="package://my_robot_description/meshes/R_R04_Link.STL" />
      </geometry>
      <material
        name="">
        <color
          rgba="0.79216 0.81961 0.93333 1" />
      </material>
    </visual>
    <collision>
      <origin
        xyz="0 0 0"
        rpy="0 0 0" />
      <geometry>
        <mesh
          filename="package://my_robot_description/meshes/R_R04_Link.STL" />
      </geometry>
    </collision>
  </link>
  <joint
    name="R_R04_Joint"
    type="revolute">
    <origin
      xyz="0 0.0031 0.43"
      rpy="0 0 0" />
    <parent
      link="R_R03_Link" />
    <child
      link="R_R04_Link" />
    <axis
      xyz="0 1 0" />
    <limit
      lower="-6.2832"
      upper="6.2832"
      effort="100.0"
      velocity="2.0" />
  </joint>
  <link
    name="R_R05_Link">
    <inertial>
      <origin
        xyz="4.8544E-06 -0.0047046 0.046075"
        rpy="0 0 0" />
      <mass
        value="0.82449" />
      <inertia
        ixx="0.0010544"
        ixy="-7.6266E-08"
        ixz="3.7967E-08"
        iyy="0.00086962"
        iyz="0.00011863"
        izz="0.0010023" />
    </inertial>
    <visual>
      <origin
        xyz="0 0 0"
        rpy="0 0 0" />
      <geometry>
        <mesh
          filename="package://my_robot_description/meshes/R_R05_Link.STL" />
      </geometry>
      <material
        name="">
        <color
          rgba="0.79216 0.81961 0.93333 1" />
      </material>
    </visual>
    <collision>
      <origin
        xyz="0 0 0"
        rpy="0 0 0" />
      <geometry>
        <mesh
          filename="package://my_robot_description/meshes/R_R05_Link.STL" />
      </geometry>
    </collision>
  </link>
  <joint
    name="R_R05_Joint"
    type="revolute">
    <origin
      xyz="0 -0.0707 0.0673"
      rpy="0 0 0" />
    <parent
      link="R_R04_Link" />
    <child
      link="R_R05_Link" />
    <axis
      xyz="0 0 -1" />
    <limit
      lower="-6.2832"
      upper="6.2832"
      effort="100.0"
      velocity="2.0" />
  </joint>
  <link
    name="R_R06_Link">
    <inertial>
      <origin
        xyz="-0.0002141 -0.061538 -0.026956"
        rpy="0 0 0" />
      <mass
        value="1.6652" />
      <inertia
        ixx="0.00080037"
        ixy="-2.9449E-06"
        ixz="2.3339E-06"
        iyy="0.0014906"
        iyz="-4.2122E-06"
        izz="0.00093729" />
    </inertial>
    <visual>
      <origin
        xyz="0 0 0"
        rpy="0 0 0" />
      <geometry>
        <mesh
          filename="package://my_robot_description/meshes/R_R06_Link.STL" />
      </geometry>
      <material
        name="">
        <color
          rgba="0.75294 0.75294 0.75294 1" />
      </material>
    </visual>
    <collision>
      <origin
        xyz="0 0 0"
        rpy="0 0 0" />
      <geometry>
        <mesh
          filename="package://my_robot_description/meshes/R_R06_Link.STL" />
      </geometry>
    </collision>
  </link>
  <joint
    name="R_R06_Joint"
    type="revolute">
    <origin
      xyz="0 -0.0673 0.0507"
      rpy="0 0 0" />
    <parent
      link="R_R05_Link" />
    <child
      link="R_R06_Link" />
    <axis
      xyz="0 1 0" />
    <limit
      lower="-6.2832"
      upper="6.2832"
      effort="100.0"
      velocity="2.0" />
  </joint>
  <link
    name="L_R00_Link">
    <inertial>
      <origin
        xyz="-5.7685E-05 0.00010433 0.065475"
        rpy="0 0 0" />
      <mass
        value="0.94896" />
      <inertia
        ixx="0.0029607"
        ixy="-1.0113E-06"
        ixz="-5.2729E-06"
        iyy="0.0026222"
        iyz="2.8851E-06"
        izz="0.0039906" />
    </inertial>
    <visual>
      <origin
        xyz="0 0 0"
        rpy="0 0 0" />
      <geometry>
        <mesh
          filename="package://my_robot_description/meshes/L_R00_Link.STL" />
      </geometry>
      <material
        name="">
        <color
          rgba="1 1 1 1" />
      </material>
    </visual>
    <collision>
      <origin
        xyz="0 0 0"
        rpy="0 0 0" />
      <geometry>
        <mesh
          filename="package://my_robot_description/meshes/L_R00_Link.STL" />
      </geometry>
    </collision>
  </link>
  <joint
    name="L_R00_Joint"
    type="fixed">
    <origin
      xyz="-0.3015 0.001 0.8295"
      rpy="0 0 0" />
    <parent
      link="base_link" />
    <child
      link="L_R00_Link" />
    <axis
      xyz="0 0 0" />
  </joint>
  <link
    name="L_R01_Link">
    <inertial>
      <origin
        xyz="8.7722E-06 -0.010199 0.087734"
        rpy="0 0 0" />
      <mass
        value="3.6238" />
      <inertia
        ixx="0.011748"
        ixy="5.2386E-08"
        ixz="-5.1621E-07"
        iyy="0.010978"
        iyz="0.0014505"
        izz="0.011872" />
    </inertial>
    <visual>
      <origin
        xyz="0 0 0"
        rpy="0 0 0" />
      <geometry>
        <mesh
          filename="package://my_robot_description/meshes/L_R01_Link.STL" />
      </geometry>
      <material
        name="">
        <color
          rgba="1 1 1 1" />
      </material>
    </visual>
    <collision>
      <origin
        xyz="0 0 0"
        rpy="0 0 0" />
      <geometry>
        <mesh
          filename="package://my_robot_description/meshes/L_R01_Link.STL" />
      </geometry>
    </collision>
  </link>
  <joint
    name="L_R01_Joint"
    type="revolute">
    <origin
      xyz="0 0 0.101"
      rpy="0 0 0" />
    <parent
      link="L_R00_Link" />
    <child
      link="L_R01_Link" />
    <axis
      xyz="0 0 1" />
    <limit
      lower="-6.2832"
      upper="6.2832"
      effort="100.0"
      velocity="2.0" />
  </joint>
  <link
    name="L_R02_Link">
    <inertial>
      <origin
        xyz="-3.3951E-06 -0.090301 0.22698"
        rpy="0 0 0" />
      <mass
        value="10.025" />
      <inertia
        ixx="0.082438"
        ixy="-6.6879E-07"
        ixz="-6.8997E-08"
        iyy="0.082584"
        iyz="0.0010302"
        izz="0.023126" />
    </inertial>
    <visual>
      <origin
        xyz="0 0 0"
        rpy="0 0 0" />
      <geometry>
        <mesh
          filename="package://my_robot_description/meshes/L_R02_Link.STL" />
      </geometry>
      <material
        name="">
        <color
          rgba="1 1 1 1" />
      </material>
    </visual>
    <collision>
      <origin
        xyz="0 0 0"
        rpy="0 0 0" />
      <geometry>
        <mesh
          filename="package://my_robot_description/meshes/L_R02_Link.STL" />
      </geometry>
    </collision>
  </link>
  <joint
    name="L_R02_Joint"
    type="revolute">
    <origin
      xyz="0 -0.089 0.0915"
      rpy="0 0 0" />
    <parent
      link="L_R01_Link" />
    <child
      link="L_R02_Link" />
    <axis
      xyz="0 -1 0" />
    <limit
      lower="-6.2832"
      upper="6.2832"
      effort="100.0"
      velocity="2.0" />
  </joint>
  <link
    name="L_R03_Link">
    <inertial>
      <origin
        xyz="3.7356E-06 0.064682 0.19279"
        rpy="0 0 0" />
      <mass
        value="4.1459" />
      <inertia
        ixx="0.021426"
        ixy="-2.9841E-07"
        ixz="9.9664E-08"
        iyy="0.021"
        iyz="-0.00034616"
        izz="0.0057151" />
    </inertial>
    <visual>
      <origin
        xyz="0 0 0"
        rpy="0 0 0" />
      <geometry>
        <mesh
          filename="package://my_robot_description/meshes/L_R03_Link.STL" />
      </geometry>
      <material
        name="">
        <color
          rgba="1 1 1 1" />
      </material>
    </visual>
    <collision>
      <origin
        xyz="0 0 0"
        rpy="0 0 0" />
      <geometry>
        <mesh
          filename="package://my_robot_description/meshes/L_R03_Link.STL" />
      </geometry>
    </collision>
  </link>
  <joint
    name="L_R03_Joint"
    type="revolute">
    <origin
      xyz="0 -0.0209 0.552"
      rpy="0 0 0" />
    <parent
      link="L_R02_Link" />
    <child
      link="L_R03_Link" />
    <axis
      xyz="0 1 0" />
    <limit
      lower="-6.2832"
      upper="6.2832"
      effort="100.0"
      velocity="2.0" />
  </joint>
  <link
    name="L_R04_Link">
    <inertial>
      <origin
        xyz="-2.9854E-06 -0.059008 0.0041121"
        rpy="0 0 0" />
      <mass
        value="0.94334" />
      <inertia
        ixx="0.0014296"
        ixy="3.0491E-08"
        ixz="-4.9808E-08"
        iyy="0.0011354"
        iyz="0.00019671"
        izz="0.0012242" />
    </inertial>
    <visual>
      <origin
        xyz="0 0 0"
        rpy="0 0 0" />
      <geometry>
        <mesh
          filename="package://my_robot_description/meshes/L_R04_Link.STL" />
      </geometry>
      <material
        name="">
        <color
          rgba="0.79216 0.81961 0.93333 1" />
      </material>
    </visual>
    <collision>
      <origin
        xyz="0 0 0"
        rpy="0 0 0" />
      <geometry>
        <mesh
          filename="package://my_robot_description/meshes/L_R04_Link.STL" />
      </geometry>
    </collision>
  </link>
  <joint
    name="L_R04_Joint"
    type="revolute">
    <origin
      xyz="0 0.0031 0.43"
      rpy="0 0 0" />
    <parent
      link="L_R03_Link" />
    <child
      link="L_R04_Link" />
    <axis
      xyz="0 1 0" />
    <limit
      lower="-6.2832"
      upper="6.2832"
      effort="100.0"
      velocity="2.0" />
  </joint>
  <link
    name="L_R05_Link">
    <inertial>
      <origin
        xyz="-5.4904E-05 -0.0047043 0.046075"
        rpy="0 0 0" />
      <mass
        value="0.82449" />
      <inertia
        ixx="0.0010543"
        ixy="-2.4228E-06"
        ixz="1.5451E-06"
        iyy="0.00086965"
        iyz="0.00011862"
        izz="0.0010023" />
    </inertial>
    <visual>
      <origin
        xyz="0 0 0"
        rpy="0 0 0" />
      <geometry>
        <mesh
          filename="package://my_robot_description/meshes/L_R05_Link.STL" />
      </geometry>
      <material
        name="">
        <color
          rgba="0.79216 0.81961 0.93333 1" />
      </material>
    </visual>
    <collision>
      <origin
        xyz="0 0 0"
        rpy="0 0 0" />
      <geometry>
        <mesh
          filename="package://my_robot_description/meshes/L_R05_Link.STL" />
      </geometry>
    </collision>
  </link>
  <joint
    name="L_R05_Joint"
    type="revolute">
    <origin
      xyz="0 -0.0707 0.0673"
      rpy="0 0 0" />
    <parent
      link="L_R04_Link" />
    <child
      link="L_R05_Link" />
    <axis
      xyz="0 0 -1" />
    <limit
      lower="-6.2832"
      upper="6.2832"
      effort="100.0"
      velocity="2.0" />
  </joint>
  <link
    name="L_R06_Link">
    <inertial>
      <origin
        xyz="-0.002204 -0.061333 -0.025591"
        rpy="0 0 0" />
      <mass
        value="1.6639" />
      <inertia
        ixx="0.00078855"
        ixy="6.8494E-06"
        ixz="-1.8668E-06"
        iyy="0.0014753"
        iyz="-4.5567E-06"
        izz="0.00093201" />
    </inertial>
    <visual>
      <origin
        xyz="0 0 0"
        rpy="0 0 0" />
      <geometry>
        <mesh
          filename="package://my_robot_description/meshes/L_R06_Link.STL" />
      </geometry>
      <material
        name="">
        <color
          rgba="0.75294 0.75294 0.75294 1" />
      </material>
    </visual>
    <collision>
      <origin
        xyz="0 0 0"
        rpy="0 0 0" />
      <geometry>
        <mesh
          filename="package://my_robot_description/meshes/L_R06_Link.STL" />
      </geometry>
    </collision>
  </link>
  <joint
    name="L_R06_Joint"
    type="revolute">
    <origin
      xyz="-0.00085495 -0.067295 0.0507"
      rpy="0 0 0" />
    <parent
      link="L_R05_Link" />
    <child
      link="L_R06_Link" />
    <axis
      xyz="0.012704 0.99992 0" />
    <limit
      lower="-6.2832"
      upper="6.2832"
      effort="100.0"
      velocity="2.0" />
  </joint>
</robot>
